Workbook

Sheet Dashboard
A1: Credit Card Benefits & Annual Fee Tracker
A2: Portfolio rollup as of | B2: =TODAY()
A3: Total annual fees charged (active cards) | B3: =SUMIF($G$9:$G$28,"Active",$H$9:$H$28) | C3: Credits used - statement credits | D3: =SUMIF($G$9:$G$28,"Active",$J$9:$J$28) | E3: Credits used - incl. estimated | F3: =SUMIF($G$9:$G$28,"Active",$K$9:$K$28) | G3: Remaining credit value | H3: =SUMIF($G$9:$G$28,"Active",$L$9:$L$28)
A4: Portfolio net benefit - statement credits | B4: =SUMIF($G$9:$G$28,"Active",$M$9:$M$28) | C4: Portfolio net benefit - incl. estimated | D4: =SUMIF($G$9:$G$28,"Active",$N$9:$N$28) | E4: Portfolio result | F4: =IF($B$4>=0,"POSITIVE","NEGATIVE") | G4: Credit utilization % | H4: =IF($I$29=0,"",$F$3/$I$29)
A5: Cards tracked / active | B5: =COUNTA($A$9:$A$28)&" / "&COUNTIF($G$9:$G$28,"Active") | C5: Total months held (active) | D5: =SUMIF($G$9:$G$28,"Active",$E$9:$E$28) | E5: Average months held (active) | F5: =IFERROR(AVERAGEIF($G$9:$G$28,"Active",$E$9:$E$28),"") | G5: Credits at risk (<=30 days) | H5: =SUMIF($G$9:$G$28,"Active",$Q$9:$Q$28)
A6: Nearest expiry across active cards (days) | B6: =IF(MIN($S$9:$S$28)>=9999,"",MIN($S$9:$S$28))
A8: Card (tab) | B8: Issuer | C8: Product | D8: Open date | E8: Months held | F8: Years held | G8: Card status | H8: AF this cycle | I8: Max annual (SC+est.) | J8: Used - SC | K8: Used - incl. est. | L8: Remaining | M8: Net - SC | N8: Net - incl. est. | O8: Result | P8: Util % | Q8: At risk | R8: Nearest expiry (d)
A9: =HYPERLINK("#'CHASE-UNITED-QUEST'!A1","CHASE-UNITED-QUEST") | B9: ='CHASE-UNITED-QUEST'!$B$2 | C9: ='CHASE-UNITED-QUEST'!$B$3 | D9: ='CHASE-UNITED-QUEST'!$B$5 | E9: ='CHASE-UNITED-QUEST'!$B$6 | F9: ='CHASE-UNITED-QUEST'!$B$7 | G9: ='CHASE-UNITED-QUEST'!$B$4 | H9: ='CHASE-UNITED-QUEST'!$B$12 | I9: ='CHASE-UNITED-QUEST'!$E$5 | J9: ='CHASE-UNITED-QUEST'!$E$3 | K9: ='CHASE-UNITED-QUEST'!$E$4 | L9: ='CHASE-UNITED-QUEST'!$E$6 | M9: ='CHASE-UNITED-QUEST'!$E$8 | N9: ='CHASE-UNITED-QUEST'!$E$9 | O9: ='CHASE-UNITED-QUEST'!$E$10 | P9: ='CHASE-UNITED-QUEST'!$E$12 | Q9: ='CHASE-UNITED-QUEST'!$E$13 | R9: ='CHASE-UNITED-QUEST'!$E$14 | S9: =IF(AND($G9="Active",ISNUMBER($R9)),$R9,9999)
A10: =HYPERLINK("#'CHASE-BOUNDLESS'!A1","CHASE-BOUNDLESS") | B10: ='CHASE-BOUNDLESS'!$B$2 | C10: ='CHASE-BOUNDLESS'!$B$3 | D10: ='CHASE-BOUNDLESS'!$B$5 | E10: ='CHASE-BOUNDLESS'!$B$6 | F10: ='CHASE-BOUNDLESS'!$B$7 | G10: ='CHASE-BOUNDLESS'!$B$4 | H10: ='CHASE-BOUNDLESS'!$B$12 | I10: ='CHASE-BOUNDLESS'!$E$5 | J10: ='CHASE-BOUNDLESS'!$E$3 | K10: ='CHASE-BOUNDLESS'!$E$4 | L10: ='CHASE-BOUNDLESS'!$E$6 | M10: ='CHASE-BOUNDLESS'!$E$8 | N10: ='CHASE-BOUNDLESS'!$E$9 | O10: ='CHASE-BOUNDLESS'!$E$10 | P10: ='CHASE-BOUNDLESS'!$E$12 | Q10: ='CHASE-BOUNDLESS'!$E$13 | R10: ='CHASE-BOUNDLESS'!$E$14 | S10: =IF(AND($G10="Active",ISNUMBER($R10)),$R10,9999)
A11: =HYPERLINK("#'CHASE-CSP'!A1","CHASE-CSP") | B11: ='CHASE-CSP'!$B$2 | C11: ='CHASE-CSP'!$B$3 | D11: ='CHASE-CSP'!$B$5 | E11: ='CHASE-CSP'!$B$6 | F11: ='CHASE-CSP'!$B$7 | G11: ='CHASE-CSP'!$B$4 | H11: ='CHASE-CSP'!$B$12 | I11: ='CHASE-CSP'!$E$5 | J11: ='CHASE-CSP'!$E$3 | K11: ='CHASE-CSP'!$E$4 | L11: ='CHASE-CSP'!$E$6 | M11: ='CHASE-CSP'!$E$8 | N11: ='CHASE-CSP'!$E$9 | O11: ='CHASE-CSP'!$E$10 | P11: ='CHASE-CSP'!$E$12 | Q11: ='CHASE-CSP'!$E$13 | R11: ='CHASE-CSP'!$E$14 | S11: =IF(AND($G11="Active",ISNUMBER($R11)),$R11,9999)
S12: =IF(AND($G12="Active",ISNUMBER($R12)),$R12,9999)
S13: =IF(AND($G13="Active",ISNUMBER($R13)),$R13,9999)
S14: =IF(AND($G14="Active",ISNUMBER($R14)),$R14,9999)
S15: =IF(AND($G15="Active",ISNUMBER($R15)),$R15,9999)
S16: =IF(AND($G16="Active",ISNUMBER($R16)),$R16,9999)
S17: =IF(AND($G17="Active",ISNUMBER($R17)),$R17,9999)
S18: =IF(AND($G18="Active",ISNUMBER($R18)),$R18,9999)
S19: =IF(AND($G19="Active",ISNUMBER($R19)),$R19,9999)
S20: =IF(AND($G20="Active",ISNUMBER($R20)),$R20,9999)
S21: =IF(AND($G21="Active",ISNUMBER($R21)),$R21,9999)
S22: =IF(AND($G22="Active",ISNUMBER($R22)),$R22,9999)
S23: =IF(AND($G23="Active",ISNUMBER($R23)),$R23,9999)
... S28: =IF(AND($G28="Active",ISNUMBER($R28)),$R28,9999)
E29: =IFERROR(AVERAGEIF($G$9:$G$28,"Active",$E$9:$E$28),"") | H29: =SUMIF($G$9:$G$28,"Active",$H$9:$H$28) | I29: =SUMIF($G$9:$G$28,"Active",$I$9:$I$28) | J29: =SUMIF($G$9:$G$28,"Active",$J$9:$J$28) | K29: =SUMIF($G$9:$G$28,"Active",$K$9:$K$28) | L29: =SUMIF($G$9:$G$28,"Active",$L$9:$L$28) | M29: =SUMIF($G$9:$G$28,"Active",$M$9:$M$28) | N29: =SUMIF($G$9:$G$28,"Active",$N$9:$N$28) | O29: =IF($M$29>=0,"POSITIVE","NEGATIVE") | P29: =IF($I$29=0,"",$K$29/$I$29) | Q29: =SUMIF($G$9:$G$28,"Active",$Q$9:$Q$28)
A31: How to use
A32: - Enter the AMOUNT you used in the month cell (e.g. 150 of a 200 credit). Green = counted. Blank = not used.
A33: - If you enter more than the credit is worth, the workbook counts only the credit amount - a single cell is capped at 'Value/cycle', and the row total is capped at 'Max annual'.
A34: - Orange cell = you entered more than that cycle's credit (capped automatically). Red banner = two uses inside the same quarter/half.
A35: - Net benefit (statement credits) = used statement credits - annual fees charged. The 'incl. estimated' columns add perk values you set yourself.
A36: - Cardmember-year credits reset on the card's anniversary, not Jan 1 - their month columns run from the AF posting month in column A10 of the card sheet.
A37: - To add a card: copy the TEMPLATE tab, rename it, then copy a row in this table and Find/Replace the tab name.
A38: - Card tabs group rows into sections by BASIS: SC (real statement credits - these move your net benefit), EST (your estimates), ACCESS (perks, no dollars).
A39: - TYPE YOUR USAGE ON THE CARD TAB, in the month column. The 'Benefits' tab is read-only - typing there breaks the link.
A40: - If a number you typed did not change the totals: check the row's Basis (ACCESS rows never add dollars) and check you typed in the MONTH column, not in 'Value/cycle'.
A41: - Amber on 'At risk' means an unused credit expires within 30 days.

Sheet Benefits
A1: Every benefit, every card - one live list, grouped by Basis
A2: All values, usage and reset dates are formulas pointing at the card tabs. Enter your usage on the CARD TAB - do not type in this sheet, it will break the link.
A4: Card | B4: Benefit | C4: Basis | D4: Cycle | E4: Resets on | F4: Value/cycle | G4: Max annual | H4: Used | I4: Remaining | J4: Status | K4: Note / source | L4: Open
A5: ='CHASE-UNITED-QUEST'!$B$1 | B5: ='CHASE-UNITED-QUEST'!$A21 | C5: ='CHASE-UNITED-QUEST'!$B21 | D5: ='CHASE-UNITED-QUEST'!$C21 | E5: =IFERROR('CHASE-UNITED-QUEST'!$J21,"") | F5: ='CHASE-UNITED-QUEST'!$D21 | G5: =IF('CHASE-UNITED-QUEST'!$F21="","",'CHASE-UNITED-QUEST'!$F21) | H5: =IF('CHASE-UNITED-QUEST'!$G21="","",'CHASE-UNITED-QUEST'!$G21) | I5: =IF('CHASE-UNITED-QUEST'!$H21="","",'CHASE-UNITED-QUEST'!$H21) | J5: =IF(ISNUMBER(SEARCH("PENDING",'CHASE-UNITED-QUEST'!$Z21&"")),"PENDING","") | K5: =IF('CHASE-UNITED-QUEST'!$Z21="","",'CHASE-UNITED-QUEST'!$Z21) | L5: =HYPERLINK("#'CHASE-UNITED-QUEST'!A21","open")
A6: ='CHASE-UNITED-QUEST'!$B$1 | B6: ='CHASE-UNITED-QUEST'!$A22 | C6: ='CHASE-UNITED-QUEST'!$B22 | D6: ='CHASE-UNITED-QUEST'!$C22 | E6: =IFERROR('CHASE-UNITED-QUEST'!$J22,"") | F6: ='CHASE-UNITED-QUEST'!$D22 | G6: =IF('CHASE-UNITED-QUEST'!$F22="","",'CHASE-UNITED-QUEST'!$F22) | H6: =IF('CHASE-UNITED-QUEST'!$G22="","",'CHASE-UNITED-QUEST'!$G22) | I6: =IF('CHASE-UNITED-QUEST'!$H22="","",'CHASE-UNITED-QUEST'!$H22) | J6: =IF(ISNUMBER(SEARCH("PENDING",'CHASE-UNITED-QUEST'!$Z22&"")),"PENDING","") | K6: =IF('CHASE-UNITED-QUEST'!$Z22="","",'CHASE-UNITED-QUEST'!$Z22) | L6: =HYPERLINK("#'CHASE-UNITED-QUEST'!A22","open")
A7: ='CHASE-UNITED-QUEST'!$B$1 | B7: ='CHASE-UNITED-QUEST'!$A27 | C7: ='CHASE-UNITED-QUEST'!$B27 | D7: ='CHASE-UNITED-QUEST'!$C27 | E7: =IFERROR('CHASE-UNITED-QUEST'!$J27,"") | F7: ='CHASE-UNITED-QUEST'!$D27 | G7: =IF('CHASE-UNITED-QUEST'!$F27="","",'CHASE-UNITED-QUEST'!$F27) | H7: =IF('CHASE-UNITED-QUEST'!$G27="","",'CHASE-UNITED-QUEST'!$G27) | I7: =IF('CHASE-UNITED-QUEST'!$H27="","",'CHASE-UNITED-QUEST'!$H27) | J7: =IF(ISNUMBER(SEARCH("PENDING",'CHASE-UNITED-QUEST'!$Z27&"")),"PENDING","") | K7: =IF('CHASE-UNITED-QUEST'!$Z27="","",'CHASE-UNITED-QUEST'!$Z27) | L7: =HYPERLINK("#'CHASE-UNITED-QUEST'!A27","open")
A8: ='CHASE-UNITED-QUEST'!$B$1 | B8: ='CHASE-UNITED-QUEST'!$A28 | C8: ='CHASE-UNITED-QUEST'!$B28 | D8: ='CHASE-UNITED-QUEST'!$C28 | E8: =IFERROR('CHASE-UNITED-QUEST'!$J28,"") | F8: ='CHASE-UNITED-QUEST'!$D28 | G8: =IF('CHASE-UNITED-QUEST'!$F28="","",'CHASE-UNITED-QUEST'!$F28) | H8: =IF('CHASE-UNITED-QUEST'!$G28="","",'CHASE-UNITED-QUEST'!$G28) | I8: =IF('CHASE-UNITED-QUEST'!$H28="","",'CHASE-UNITED-QUEST'!$H28) | J8: =IF(ISNUMBER(SEARCH("PENDING",'CHASE-UNITED-QUEST'!$Z28&"")),"PENDING","") | K8: =IF('CHASE-UNITED-QUEST'!$Z28="","",'CHASE-UNITED-QUEST'!$Z28) | L8: =HYPERLINK("#'CHASE-UNITED-QUEST'!A28","open")
A9: ='CHASE-UNITED-QUEST'!$B$1 | B9: ='CHASE-UNITED-QUEST'!$A29 | C9: ='CHASE-UNITED-QUEST'!$B29 | D9: ='CHASE-UNITED-QUEST'!$C29 | E9: =IFERROR('CHASE-UNITED-QUEST'!$J29,"") | F9: ='CHASE-UNITED-QUEST'!$D29 | G9: =IF('CHASE-UNITED-QUEST'!$F29="","",'CHASE-UNITED-QUEST'!$F29) | H9: =IF('CHASE-UNITED-QUEST'!$G29="","",'CHASE-UNITED-QUEST'!$G29) | I9: =IF('CHASE-UNITED-QUEST'!$H29="","",'CHASE-UNITED-QUEST'!$H29) | J9: =IF(ISNUMBER(SEARCH("PENDING",'CHASE-UNITED-QUEST'!$Z29&"")),"PENDING","") | K9: =IF('CHASE-UNITED-QUEST'!$Z29="","",'CHASE-UNITED-QUEST'!$Z29) | L9: =HYPERLINK("#'CHASE-UNITED-QUEST'!A29","open")
A10: ='CHASE-UNITED-QUEST'!$B$1 | B10: ='CHASE-UNITED-QUEST'!$A30 | C10: ='CHASE-UNITED-QUEST'!$B30 | D10: ='CHASE-UNITED-QUEST'!$C30 | E10: =IFERROR('CHASE-UNITED-QUEST'!$J30,"") | F10: ='CHASE-UNITED-QUEST'!$D30 | G10: =IF('CHASE-UNITED-QUEST'!$F30="","",'CHASE-UNITED-QUEST'!$F30) | H10: =IF('CHASE-UNITED-QUEST'!$G30="","",'CHASE-UNITED-QUEST'!$G30) | I10: =IF('CHASE-UNITED-QUEST'!$H30="","",'CHASE-UNITED-QUEST'!$H30) | J10: =IF(ISNUMBER(SEARCH("PENDING",'CHASE-UNITED-QUEST'!$Z30&"")),"PENDING","") | K10: =IF('CHASE-UNITED-QUEST'!$Z30="","",'CHASE-UNITED-QUEST'!$Z30) | L10: =HYPERLINK("#'CHASE-UNITED-QUEST'!A30","open")
A11: ='CHASE-UNITED-QUEST'!$B$1 | B11: ='CHASE-UNITED-QUEST'!$A35 | C11: ='CHASE-UNITED-QUEST'!$B35 | D11: ='CHASE-UNITED-QUEST'!$C35 | E11: =IFERROR('CHASE-UNITED-QUEST'!$J35,"") | F11: ='CHASE-UNITED-QUEST'!$D35 | G11: =IF('CHASE-UNITED-QUEST'!$F35="","",'CHASE-UNITED-QUEST'!$F35) | H11: =IF('CHASE-UNITED-QUEST'!$G35="","",'CHASE-UNITED-QUEST'!$G35) | I11: =IF('CHASE-UNITED-QUEST'!$H35="","",'CHASE-UNITED-QUEST'!$H35) | J11: =IF(ISNUMBER(SEARCH("PENDING",'CHASE-UNITED-QUEST'!$Z35&"")),"PENDING","") | K11: =IF('CHASE-UNITED-QUEST'!$Z35="","",'CHASE-UNITED-QUEST'!$Z35) | L11: =HYPERLINK("#'CHASE-UNITED-QUEST'!A35","open")
A12: ='CHASE-UNITED-QUEST'!$B$1 | B12: ='CHASE-UNITED-QUEST'!$A40 | C12: ='CHASE-UNITED-QUEST'!$B40 | D12: ='CHASE-UNITED-QUEST'!$C40 | E12: =IF('CHASE-UNITED-QUEST'!$H40="","",'CHASE-UNITED-QUEST'!$H40) | F12: ='CHASE-UNITED-QUEST'!$D40 | G12: ='CHASE-UNITED-QUEST'!$E40 | H12: ='CHASE-UNITED-QUEST'!$J40 | I12: =IF(ISNUMBER('CHASE-UNITED-QUEST'!$D40),MAX(0,'CHASE-UNITED-QUEST'!$D40-'CHASE-UNITED-QUEST'!$J40),"") | J12: =IF(ISNUMBER(SEARCH("PENDING",'CHASE-UNITED-QUEST'!$Z40&"")),"PENDING","") | K12: =IF('CHASE-UNITED-QUEST'!$Z40="","",'CHASE-UNITED-QUEST'!$Z40) | L12: =HYPERLINK("#'CHASE-UNITED-QUEST'!A40","open")
A13: ='CHASE-BOUNDLESS'!$B$1 | B13: ='CHASE-BOUNDLESS'!$A21 | C13: ='CHASE-BOUNDLESS'!$B21 | D13: ='CHASE-BOUNDLESS'!$C21 | E13: =IFERROR('CHASE-BOUNDLESS'!$J21,"") | F13: ='CHASE-BOUNDLESS'!$D21 | G13: =IF('CHASE-BOUNDLESS'!$F21="","",'CHASE-BOUNDLESS'!$F21) | H13: =IF('CHASE-BOUNDLESS'!$G21="","",'CHASE-BOUNDLESS'!$G21) | I13: =IF('CHASE-BOUNDLESS'!$H21="","",'CHASE-BOUNDLESS'!$H21) | J13: =IF(ISNUMBER(SEARCH("PENDING",'CHASE-BOUNDLESS'!$Z21&"")),"PENDING","") | K13: =IF('CHASE-BOUNDLESS'!$Z21="","",'CHASE-BOUNDLESS'!$Z21) | L13: =HYPERLINK("#'CHASE-BOUNDLESS'!A21","open")
A14: ='CHASE-BOUNDLESS'!$B$1 | B14: ='CHASE-BOUNDLESS'!$A26 | C14: ='CHASE-BOUNDLESS'!$B26 | D14: ='CHASE-BOUNDLESS'!$C26 | E14: =IFERROR('CHASE-BOUNDLESS'!$J26,"") | F14: ='CHASE-BOUNDLESS'!$D26 | G14: =IF('CHASE-BOUNDLESS'!$F26="","",'CHASE-BOUNDLESS'!$F26) | H14: =IF('CHASE-BOUNDLESS'!$G26="","",'CHASE-BOUNDLESS'!$G26) | I14: =IF('CHASE-BOUNDLESS'!$H26="","",'CHASE-BOUNDLESS'!$H26) | J14: =IF(ISNUMBER(SEARCH("PENDING",'CHASE-BOUNDLESS'!$Z26&"")),"PENDING","") | K14: =IF('CHASE-BOUNDLESS'!$Z26="","",'CHASE-BOUNDLESS'!$Z26) | L14: =HYPERLINK("#'CHASE-BOUNDLESS'!A26","open")
A15: ='CHASE-BOUNDLESS'!$B$1 | B15: ='CHASE-BOUNDLESS'!$A31 | C15: ='CHASE-BOUNDLESS'!$B31 | D15: ='CHASE-BOUNDLESS'!$C31 | E15: =IFERROR('CHASE-BOUNDLESS'!$J31,"") | F15: ='CHASE-BOUNDLESS'!$D31 | G15: =IF('CHASE-BOUNDLESS'!$F31="","",'CHASE-BOUNDLESS'!$F31) | H15: =IF('CHASE-BOUNDLESS'!$G31="","",'CHASE-BOUNDLESS'!$G31) | I15: =IF('CHASE-BOUNDLESS'!$H31="","",'CHASE-BOUNDLESS'!$H31) | J15: =IF(ISNUMBER(SEARCH("PENDING",'CHASE-BOUNDLESS'!$Z31&"")),"PENDING","") | K15: =IF('CHASE-BOUNDLESS'!$Z31="","",'CHASE-BOUNDLESS'!$Z31) | L15: =HYPERLINK("#'CHASE-BOUNDLESS'!A31","open")
A16: ='CHASE-CSP'!$B$1 | B16: ='CHASE-CSP'!$A21 | C16: ='CHASE-CSP'!$B21 | D16: ='CHASE-CSP'!$C21 | E16: =IFERROR('CHASE-CSP'!$J21,"") | F16: ='CHASE-CSP'!$D21 | G16: =IF('CHASE-CSP'!$F21="","",'CHASE-CSP'!$F21) | H16: =IF('CHASE-CSP'!$G21="","",'CHASE-CSP'!$G21) | I16: =IF('CHASE-CSP'!$H21="","",'CHASE-CSP'!$H21) | J16: =IF(ISNUMBER(SEARCH("PENDING",'CHASE-CSP'!$Z21&"")),"PENDING","") | K16: =IF('CHASE-CSP'!$Z21="","",'CHASE-CSP'!$Z21) | L16: =HYPERLINK("#'CHASE-CSP'!A21","open")
A17: ='CHASE-CSP'!$B$1 | B17: ='CHASE-CSP'!$A26 | C17: ='CHASE-CSP'!$B26 | D17: ='CHASE-CSP'!$C26 | E17: =IFERROR('CHASE-CSP'!$J26,"") | F17: ='CHASE-CSP'!$D26 | G17: =IF('CHASE-CSP'!$F26="","",'CHASE-CSP'!$F26) | H17: =IF('CHASE-CSP'!$G26="","",'CHASE-CSP'!$G26) | I17: =IF('CHASE-CSP'!$H26="","",'CHASE-CSP'!$H26) | J17: =IF(ISNUMBER(SEARCH("PENDING",'CHASE-CSP'!$Z26&"")),"PENDING","") | K17: =IF('CHASE-CSP'!$Z26="","",'CHASE-CSP'!$Z26) | L17: =HYPERLINK("#'CHASE-CSP'!A26","open")
A18: ='CHASE-CSP'!$B$1 | B18: ='CHASE-CSP'!$A31 | C18: ='CHASE-CSP'!$B31 | D18: ='CHASE-CSP'!$C31 | E18: =IF('CHASE-CSP'!$H31="","",'CHASE-CSP'!$H31) | F18: ='CHASE-CSP'!$D31 | G18: ='CHASE-CSP'!$E31 | H18: ='CHASE-CSP'!$J31 | I18: =IF(ISNUMBER('CHASE-CSP'!$D31),MAX(0,'CHASE-CSP'!$D31-'CHASE-CSP'!$J31),"") | J18: =IF(ISNUMBER(SEARCH("PENDING",'CHASE-CSP'!$Z31&"")),"PENDING","") | K18: =IF('CHASE-CSP'!$Z31="","",'CHASE-CSP'!$Z31) | L18: =HYPERLINK("#'CHASE-CSP'!A31","open")

Sheet CHASE-UNITED-QUEST
A1: Card | B1: CHASE-UNITED-QUEST
A2: Issuer | B2: Chase | Z2: Annual fee $350 in 2026 (was $250 before). Open date is a PLACEHOLDER - change B5 and B10 to the real approval date.
A3: Product (exact) | B3: United Quest Card | D3: Credits used YTD - statement credits (SC) | E3: =SUMIF($B$21:$B$22,"SC",$G$21:$G$22)+SUMIF($B$27:$B$30,"SC",$G$27:$G$30)+SUMIF($B$35:$B$35,"SC",$G$35:$G$35)+SUMIFS($F$40:$F$40,$B$40:$B$40,"SC",$I$40:$I$40,"y") | G3: =HYPERLINK("#'Dashboard'!A1","< back to Dashboard") | H3: =MIN($Y$21:$Y$22,$Y$27:$Y$30,$Y$35:$Y$35)
A4: Card status | B4: Active | D4: Credits used YTD - incl. estimated (SC+EST) | E4: =SUMIF($B$21:$B$22,"SC",$G$21:$G$22)+SUMIF($B$27:$B$30,"SC",$G$27:$G$30)+SUMIF($B$35:$B$35,"SC",$G$35:$G$35)+SUMIFS($F$40:$F$40,$B$40:$B$40,"SC",$I$40:$I$40,"y")+SUMIF($B$21:$B$22,"EST",$G$21:$G$22)+SUMIF($B$27:$B$30,"EST",$G$27:$G$30)+SUMIF($B$35:$B$35,"EST",$G$35:$G$35)+SUMIFS($F$40:$F$40,$B$40:$B$40,"EST",$I$40:$I$40,"y") | H4: =SUMIF($B$21:$B$22,"SC",$F$21:$F$22)+SUMIF($B$27:$B$30,"SC",$F$27:$F$30)+SUMIF($B$35:$B$35,"SC",$F$35:$F$35)+SUMIFS($F$40:$F$40,$B$40:$B$40,"SC")
A5: Open date (approval) | B5: 46023 | D5: Max annual value (statement credits + estimated) | E5: =SUM($F$21:$F$22)+SUM($F$27:$F$30)+SUM($F$35:$F$35)+SUM($F$40:$F$40)
A6: Months held | B6: =IF($B$5="","",DATEDIF($B$5,TODAY(),"m")) | D6: Remaining annual credit value (incl. est.) | E6: =MAX(0,$E$5-$E$4)
A7: Years held | B7: =IF($B$6="","",ROUND($B$6/12,1)) | D7: Remaining - statement credits only | E7: =MAX(0,$H$4-$E$3)
A8: Annual fee (USD) | B8: 350 | D8: Net benefit - statement credits | E8: =$E$3-$B$12
A9: First-year AF waived? | D9: Net benefit - incl. estimated | E9: =$E$4-$B$12
A10: AF posting date (current cycle) | B10: 46023 | D10: Result | E10: =IF($E$8>=0,"POSITIVE","NEGATIVE")
A11: Authorized user AF (total, USD) | B11: 0 | D11: AF breakeven gap | E11: =MAX(0,-$E$8)
A12: Total AF charged (this cycle) | B12: =IF($B$9="y",0,$B$8)+$B$11 | D12: Credit utilization % | E12: =IF($E$5=0,"",$E$4/$E$5)
A13: Next AF date (projected) | B13: =EDATE($B$10,12) | D13: Credits at risk (unused, <=30 days left) | E13: =SUMPRODUCT(($Y$21:$Y$22>=0)*($Y$21:$Y$22<=30))+SUMPRODUCT(($Y$27:$Y$30>=0)*($Y$27:$Y$30<=30))+SUMPRODUCT(($Y$35:$Y$35>=0)*($Y$35:$Y$35<=30))
A14: Cardmember year start (current cycle) | B14: =IFERROR(EDATE($B$10,12*DATEDIF($B$10,TODAY(),"y")),"") | D14: Nearest expiry (days) | E14: =IF($H$3>=9999,"",$H$3)
D15: Amounts you entered (cells) | E15: =COUNT(L21:W22)+COUNT(L27:W30)+COUNT(L35:W35)+COUNTIF($I$40:$I$40,">0")
D16: Entered total before capping | E16: =SUM(L21:W22)+SUM(L27:W30)+SUM(L35:W35)+SUM($J$40:$J$40)
A17: WHERE TO TYPE: put the amount you used into the month column of that row. SC rows are real statement credits and drive your net benefit. EST rows are values you set yourself (baggage fees saved) and only count in the 'incl. estimated' totals. 'Amounts you entered' above counts how many month cells you have filled in.
A19: SECTION 1 · STATEMENT CREDITS (SC) · real money on your statement. NET BENEFIT COMES FROM HERE. Type the amount you used into the month column.
A20: Benefit | B20: Basis | C20: Cycle | D20: Value/cycle | E20: Cyc/yr | F20: Max annual | G20: Used | H20: Remaining | I20: Uses | J20: Cycle end | K20: Days left | L20: =INDEX('Ref'!$J$3:$J$14,COLUMN()-11) | M20: =INDEX('Ref'!$J$3:$J$14,COLUMN()-11) | N20: =INDEX('Ref'!$J$3:$J$14,COLUMN()-11) | O20: =INDEX('Ref'!$J$3:$J$14,COLUMN()-11) | P20: =INDEX('Ref'!$J$3:$J$14,COLUMN()-11) | Q20: =INDEX('Ref'!$J$3:$J$14,COLUMN()-11) | R20: =INDEX('Ref'!$J$3:$J$14,COLUMN()-11) | S20: =INDEX('Ref'!$J$3:$J$14,COLUMN()-11) | ... W20: =INDEX('Ref'!$J$3:$J$14,COLUMN()-11) | Z20: Notes / source
A21: Rideshare credit | B21: SC | C21: MONTHLY | D21: 8 | E21: =IF($C21="MONTHLY",12,IF($C21="QUARTERLY",4,IF($C21="SEMI-ANNUAL",2,IF($C21="CALENDAR-YEAR",1,"")))) | F21: =IF(OR($D21="",$E21=""),"",$D21*$E21) | G21: =IF($D21="","",IF(ISNUMBER($F21),MIN($X21,$F21),$X21)) | H21: =IF($F21="","",MAX(0,$F21-$G21)) | I21: =SUMPRODUCT(ISNUMBER($L21:$W21)*($L21:$W21>0)) | J21: =IF($C21="MONTHLY",EOMONTH(TODAY(),0),IF($C21="QUARTERLY",EOMONTH(DATE('Ref'!$B$1,ROUNDUP(MONTH(TODAY())/3,0)*3,1),0),IF($C21="SEMI-ANNUAL",IF(MONTH(TODAY())<=6,DATE('Ref'!$B$1,6,30),DATE('Ref'!$B$1,12,31)),DATE('Ref'!$B$1,12,31)))) | K21: =IFERROR($J21-TODAY(),"") | X21: =IF($D21="",SUM($L21:$W21),SUM($L21:$W21)-SUMIF($L21:$W21,">"&$D21)+(COUNT($L21:$W21)-COUNTIF($L21:$W21,"<="&$D21))*$D21) | Y21: =IF(AND(ISNUMBER($H21),$H21>0,ISNUMBER($K21),$K21>=0),$K21,9999) | Z21: OFFICIAL (Chase.com): up to $100 per calendar year - $8 back each month Jan-Nov and up to $12 in December. Enrollment required. December is worth more, so type 12 there if you use it
A22: Instacart credits | B22: SC | C22: MONTHLY | D22: 15 | E22: =IF($C22="MONTHLY",12,IF($C22="QUARTERLY",4,IF($C22="SEMI-ANNUAL",2,IF($C22="CALENDAR-YEAR",1,"")))) | F22: =IF(OR($D22="",$E22=""),"",$D22*$E22) | G22: =IF($D22="","",IF(ISNUMBER($F22),MIN($X22,$F22),$X22)) | H22: =IF($F22="","",MAX(0,$F22-$G22)) | I22: =SUMPRODUCT(ISNUMBER($L22:$W22)*($L22:$W22>0)) | J22: =IF($C22="MONTHLY",EOMONTH(TODAY(),0),IF($C22="QUARTERLY",EOMONTH(DATE('Ref'!$B$1,ROUNDUP(MONTH(TODAY())/3,0)*3,1),0),IF($C22="SEMI-ANNUAL",IF(MONTH(TODAY())<=6,DATE('Ref'!$B$1,6,30),DATE('Ref'!$B$1,12,31)),DATE('Ref'!$B$1,12,31)))) | K22: =IFERROR($J22-TODAY(),"") | X22: =IF($D22="",SUM($L22:$W22),SUM($L22:$W22)-SUMIF($L22:$W22,">"&$D22)+(COUNT($L22:$W22)-COUNTIF($L22:$W22,"<="&$D22))*$D22) | Y22: =IF(AND(ISNUMBER($H22),$H22>0,ISNUMBER($K22),$K22>=0),$K22,9999) | Z22: OFFICIAL (Chase.com): one $10 plus one $5 Instacart credit each month, up to $180 per calendar year. Benefits end 12/31/2027
A23: Subtotal - Section 1 | F23: =SUM($F$21:$F$22) | G23: =SUM($G$21:$G$22) | H23: =SUM($H$21:$H$22) | I23: =SUM($I$21:$I$22)
A25: SECTION 1b · STATEMENT CREDITS (SC) THAT RESET ON YOUR CARD ANNIVERSARY · the month columns follow YOUR anniversary month, not January. NET BENEFIT COMES FROM HERE.
A26: Benefit | B26: Basis | C26: Cycle | D26: Value/cycle | E26: Cyc/yr | F26: Max annual | G26: Used | H26: Remaining | I26: Uses | J26: Cycle end | K26: Days left | L26: =IFERROR(INDEX('Ref'!$J$3:$J$14,MONTH(EDATE($B$14,0)))&"-"&TEXT(EDATE($B$14,0),"yy"),"") | M26: =IFERROR(INDEX('Ref'!$J$3:$J$14,MONTH(EDATE($B$14,1)))&"-"&TEXT(EDATE($B$14,1),"yy"),"") | N26: =IFERROR(INDEX('Ref'!$J$3:$J$14,MONTH(EDATE($B$14,2)))&"-"&TEXT(EDATE($B$14,2),"yy"),"") | O26: =IFERROR(INDEX('Ref'!$J$3:$J$14,MONTH(EDATE($B$14,3)))&"-"&TEXT(EDATE($B$14,3),"yy"),"") | P26: =IFERROR(INDEX('Ref'!$J$3:$J$14,MONTH(EDATE($B$14,4)))&"-"&TEXT(EDATE($B$14,4),"yy"),"") | Q26: =IFERROR(INDEX('Ref'!$J$3:$J$14,MONTH(EDATE($B$14,5)))&"-"&TEXT(EDATE($B$14,5),"yy"),"") | R26: =IFERROR(INDEX('Ref'!$J$3:$J$14,MONTH(EDATE($B$14,6)))&"-"&TEXT(EDATE($B$14,6),"yy"),"") | S26: =IFERROR(INDEX('Ref'!$J$3:$J$14,MONTH(EDATE($B$14,7)))&"-"&TEXT(EDATE($B$14,7),"yy"),"") | T26: =IFERROR(INDEX('Ref'!$J$3:$J$14,MONTH(EDATE($B$14,8)))&"-"&TEXT(EDATE($B$14,8),"yy"),"") | U26: =IFERROR(INDEX('Ref'!$J$3:$J$14,MONTH(EDATE($B$14,9)))&"-"&TEXT(EDATE($B$14,9),"yy"),"") | V26: =IFERROR(INDEX('Ref'!$J$3:$J$14,MONTH(EDATE($B$14,10)))&"-"&TEXT(EDATE($B$14,10),"yy"),"") | W26: =IFERROR(INDEX('Ref'!$J$3:$J$14,MONTH(EDATE($B$14,11)))&"-"&TEXT(EDATE($B$14,11),"yy"),"") | Z26: Notes / source
A27: United TravelBank credit | B27: SC | C27: CARDMEMBER-YEAR | D27: 200 | E27: 1 | F27: =IF($D27="","",$D27) | G27: =IF($D27="","",IF(ISNUMBER($F27),MIN($X27,$F27),$X27)) | H27: =IF($F27="","",MAX(0,$F27-$G27)) | I27: =SUMPRODUCT(ISNUMBER($L27:$W27)*($L27:$W27>0)) | J27: =IFERROR(EDATE($B$14,12)-1,"") | K27: =IFERROR($J27-TODAY(),"") | X27: =IF($D27="",SUM($L27:$W27),SUM($L27:$W27)-SUMIF($L27:$W27,">"&$D27)+(COUNT($L27:$W27)-COUNTIF($L27:$W27,"<="&$D27))*$D27) | Y27: =IF(AND(ISNUMBER($H27),$H27>0,ISNUMBER($K27),$K27>=0),$K27,9999) | Z27: OFFICIAL (Chase.com full-terms page): '$200 Annual United Travel Credit: One $200 annual United TravelBank cash credit will automatically be added to your MileagePlus account. Annual means the year beginning with your account open date through the first statement date after your account open anniversary...' Deposited within 4 weeks of the anniversary. Must be used for a United or United Express flight; expires 12 months after issue and cannot be combined with miles or travel certificates
A28: Renowned Hotels and Resorts credit | B28: SC | C28: CARDMEMBER-YEAR | D28: 150 | E28: 1 | F28: =IF($D28="","",$D28) | G28: =IF($D28="","",IF(ISNUMBER($F28),MIN($X28,$F28),$X28)) | H28: =IF($F28="","",MAX(0,$F28-$G28)) | I28: =SUMPRODUCT(ISNUMBER($L28:$W28)*($L28:$W28>0)) | J28: =IFERROR(EDATE($B$14,12)-1,"") | K28: =IFERROR($J28-TODAY(),"") | X28: =IF($D28="",SUM($L28:$W28),SUM($L28:$W28)-SUMIF($L28:$W28,">"&$D28)+(COUNT($L28:$W28)-COUNTIF($L28:$W28,"<="&$D28))*$D28) | Y28: =IF(AND(ISNUMBER($H28),$H28>0,ISNUMBER($K28),$K28>=0),$K28,9999) | Z28: OFFICIAL (Chase.com): up to $150 back each anniversary year on prepaid hotel accommodation booked directly through Renowned Hotels and Resorts
A29: JSX credit | B29: SC | C29: CARDMEMBER-YEAR | D29: 150 | E29: 1 | F29: =IF($D29="","",$D29) | G29: =IF($D29="","",IF(ISNUMBER($F29),MIN($X29,$F29),$X29)) | H29: =IF($F29="","",MAX(0,$F29-$G29)) | I29: =SUMPRODUCT(ISNUMBER($L29:$W29)*($L29:$W29>0)) | J29: =IFERROR(EDATE($B$14,12)-1,"") | K29: =IFERROR($J29-TODAY(),"") | X29: =IF($D29="",SUM($L29:$W29),SUM($L29:$W29)-SUMIF($L29:$W29,">"&$D29)+(COUNT($L29:$W29)-COUNTIF($L29:$W29,"<="&$D29))*$D29) | Y29: =IF(AND(ISNUMBER($H29),$H29>0,ISNUMBER($K29),$K29>=0),$K29,9999) | Z29: OFFICIAL (Chase.com): up to $150 back each anniversary year when you book flights directly with JSX
A30: Avis/Budget TravelBank cash | B30: SC | C30: CARDMEMBER-YEAR | D30: 80 | E30: 1 | F30: =IF($D30="","",$D30) | G30: =IF($D30="","",IF(ISNUMBER($F30),MIN($X30,$F30),$X30)) | H30: =IF($F30="","",MAX(0,$F30-$G30)) | I30: =SUMPRODUCT(ISNUMBER($L30:$W30)*($L30:$W30>0)) | J30: =IFERROR(EDATE($B$14,12)-1,"") | K30: =IFERROR($J30-TODAY(),"") | X30: =IF($D30="",SUM($L30:$W30),SUM($L30:$W30)-SUMIF($L30:$W30,">"&$D30)+(COUNT($L30:$W30)-COUNTIF($L30:$W30,"<="&$D30))*$D30) | Y30: =IF(AND(ISNUMBER($H30),$H30>0,ISNUMBER($K30),$K30>=0),$K30,9999) | Z30: OFFICIAL (Chase.com): $40 in United TravelBank cash for your 1st and 2nd Avis or Budget rental booked via cars.united.com, up to $80 each anniversary year
A31: Subtotal - Section 1b | F31: =SUM($F$27:$F$30) | G31: =SUM($G$27:$G$30) | H31: =SUM($H$27:$H$30) | I31: =SUM($I$27:$I$30)
A33: SECTION 2 · ESTIMATED SAVINGS (EST) · Counts only in the 'incl. estimated' totals.
A34: Benefit | B34: Basis | C34: Cycle | D34: Value/cycle | E34: Cyc/yr | F34: Max annual | G34: Used | H34: Remaining | I34: Uses | J34: Cycle end | K34: Days left | L34: =INDEX('Ref'!$J$3:$J$14,COLUMN()-11) | M34: =INDEX('Ref'!$J$3:$J$14,COLUMN()-11) | N34: =INDEX('Ref'!$J$3:$J$14,COLUMN()-11) | O34: =INDEX('Ref'!$J$3:$J$14,COLUMN()-11) | P34: =INDEX('Ref'!$J$3:$J$14,COLUMN()-11) | Q34: =INDEX('Ref'!$J$3:$J$14,COLUMN()-11) | R34: =INDEX('Ref'!$J$3:$J$14,COLUMN()-11) | S34: =INDEX('Ref'!$J$3:$J$14,COLUMN()-11) | ... W34: =INDEX('Ref'!$J$3:$J$14,COLUMN()-11) | Z34: Notes / source
A35: Free checked bag | B35: EST | C35: CALENDAR-YEAR | D35: 220 | E35: =IF($C35="MONTHLY",12,IF($C35="QUARTERLY",4,IF($C35="SEMI-ANNUAL",2,IF($C35="CALENDAR-YEAR",1,"")))) | F35: =IF(OR($D35="",$E35=""),"",$D35*$E35) | G35: =IF($D35="","",IF(ISNUMBER($F35),MIN($X35,$F35),$X35)) | H35: =IF($F35="","",MAX(0,$F35-$G35)) | I35: =SUMPRODUCT(ISNUMBER($L35:$W35)*($L35:$W35>0)) | J35: =IF($C35="MONTHLY",EOMONTH(TODAY(),0),IF($C35="QUARTERLY",EOMONTH(DATE('Ref'!$B$1,ROUNDUP(MONTH(TODAY())/3,0)*3,1),0),IF($C35="SEMI-ANNUAL",IF(MONTH(TODAY())<=6,DATE('Ref'!$B$1,6,30),DATE('Ref'!$B$1,12,31)),DATE('Ref'!$B$1,12,31)))) | K35: =IFERROR($J35-TODAY(),"") | X35: =IF($D35="",SUM($L35:$W35),SUM($L35:$W35)-SUMIF($L35:$W35,">"&$D35)+(COUNT($L35:$W35)-COUNTIF($L35:$W35,"<="&$D35))*$D35) | Y35: =IF(AND(ISNUMBER($H35),$H35>0,ISNUMBER($K35),$K35>=0),$K35,9999) | Z35: OFFICIAL (Chase.com): the primary cardholder and one companion on the same reservation each get their 1st and 2nd checked bags free on United-operated flights - up to $50 for the first bag and $60 for the second, each way. D = your expected annual saving (220 = one roundtrip, two people, two bags each). Type each trip's saving into that month; capped at D. Ticket must be bought with the card
A36: Subtotal - Section 2 | F36: =SUM($F$35:$F$35) | G36: =SUM($G$35:$G$35) | H36: =SUM($H$35:$H$35) | I36: =SUM($I$35:$I$35)
A38: SECTION 4 · ONE-TIME / EVERY-N-YEARS ITEMS (SC) · no month grid - enter the amount in the 'Used?' column.
A39: Benefit | B39: Basis | C39: Cycle | D39: Value | E39: Yrs/cycle | F39: Annualized | G39: Date used | H39: Expiry / next eligible | I39: Used? (amount or y) | J39: Value captured | K39: Notes
A40: Global Entry / TSA PreCheck / NEXUS credit | B40: SC | C40: MULTI-YEAR | D40: 120 | E40: 4 | F40: =IF(AND(ISNUMBER($D40),ISNUMBER($E40)),$D40/$E40,0) | J40: =IF($I40="y",$D40,IF(ISNUMBER($I40),MIN($I40,$D40),0)) | K40: OFFICIAL (Chase.com): up to $120 every four years. Enter the amount in the 'Used?' column when you claim it
A41: Subtotal - Section 4 | D41: =SUM($D$40:$D$40) | F41: =SUM($F$40:$F$40) | J41: =SUM($J$40:$J$40)

Sheet CHASE-BOUNDLESS
A1: Card | B1: CHASE-BOUNDLESS
A2: Issuer | B2: Chase | Z2: Annual fee $95. Open date is a PLACEHOLDER - change B5 and B10 to the real approval date.
A3: Product (exact) | B3: Marriott Bonvoy Boundless | D3: Credits used YTD - statement credits (SC) | E3: =SUMIF($B$21:$B$21,"SC",$G$21:$G$21)+SUMIF($B$26:$B$26,"SC",$G$26:$G$26)+SUMIF($B$31:$B$31,"SC",$G$31:$G$31) | G3: =HYPERLINK("#'Dashboard'!A1","< back to Dashboard") | H3: =MIN($Y$21:$Y$21,$Y$26:$Y$26,$Y$31:$Y$31)
A4: Card status | B4: Active | D4: Credits used YTD - incl. estimated (SC+EST) | E4: =SUMIF($B$21:$B$21,"SC",$G$21:$G$21)+SUMIF($B$26:$B$26,"SC",$G$26:$G$26)+SUMIF($B$31:$B$31,"SC",$G$31:$G$31)+SUMIF($B$21:$B$21,"EST",$G$21:$G$21)+SUMIF($B$26:$B$26,"EST",$G$26:$G$26)+SUMIF($B$31:$B$31,"EST",$G$31:$G$31) | H4: =SUMIF($B$21:$B$21,"SC",$F$21:$F$21)+SUMIF($B$26:$B$26,"SC",$F$26:$F$26)+SUMIF($B$31:$B$31,"SC",$F$31:$F$31)
A5: Open date (approval) | B5: 46023 | D5: Max annual value (statement credits + estimated) | E5: =SUM($F$21:$F$21)+SUM($F$26:$F$26)+SUM($F$31:$F$31)
A6: Months held | B6: =IF($B$5="","",DATEDIF($B$5,TODAY(),"m")) | D6: Remaining annual credit value (incl. est.) | E6: =MAX(0,$E$5-$E$4)
A7: Years held | B7: =IF($B$6="","",ROUND($B$6/12,1)) | D7: Remaining - statement credits only | E7: =MAX(0,$H$4-$E$3)
A8: Annual fee (USD) | B8: 95 | D8: Net benefit - statement credits | E8: =$E$3-$B$12
A9: First-year AF waived? | D9: Net benefit - incl. estimated | E9: =$E$4-$B$12
A10: AF posting date (current cycle) | B10: 46023 | D10: Result | E10: =IF($E$8>=0,"POSITIVE","NEGATIVE")
A11: Authorized user AF (total, USD) | B11: 0 | D11: AF breakeven gap | E11: =MAX(0,-$E$8)
A12: Total AF charged (this cycle) | B12: =IF($B$9="y",0,$B$8)+$B$11 | D12: Credit utilization % | E12: =IF($E$5=0,"",$E$4/$E$5)
A13: Next AF date (projected) | B13: =EDATE($B$10,12) | D13: Credits at risk (unused, <=30 days left) | E13: =SUMPRODUCT(($Y$21:$Y$21>=0)*($Y$21:$Y$21<=30))+SUMPRODUCT(($Y$26:$Y$26>=0)*($Y$26:$Y$26<=30))+SUMPRODUCT(($Y$31:$Y$31>=0)*($Y$31:$Y$31<=30))
A14: Cardmember year start (current cycle) | B14: =IFERROR(EDATE($B$10,12*DATEDIF($B$10,TODAY(),"y")),"") | D14: Nearest expiry (days) | E14: =IF($H$3>=9999,"",$H$3)
D15: Amounts you entered (cells) | E15: =COUNT(L21:W21)+COUNT(L26:W26)+COUNT(L31:W31)
D16: Entered total before capping | E16: =SUM(L21:W21)+SUM(L26:W26)+SUM(L31:W31)
A17: WHERE TO TYPE: put the amount you used into the month column of that row. SC rows are real statement credits and drive your net benefit. EST rows are values you set yourself (baggage fees saved) and only count in the 'incl. estimated' totals. 'Amounts you entered' above counts how many month cells you have filled in.
A19: SECTION 1 · STATEMENT CREDITS (SC) · real money on your statement. NET BENEFIT COMES FROM HERE. Type the amount you used into the month column.
A20: Benefit | B20: Basis | C20: Cycle | D20: Value/cycle | E20: Cyc/yr | F20: Max annual | G20: Used | H20: Remaining | I20: Uses | J20: Cycle end | K20: Days left | L20: =INDEX('Ref'!$J$3:$J$14,COLUMN()-11) | M20: =INDEX('Ref'!$J$3:$J$14,COLUMN()-11) | N20: =INDEX('Ref'!$J$3:$J$14,COLUMN()-11) | O20: =INDEX('Ref'!$J$3:$J$14,COLUMN()-11) | P20: =INDEX('Ref'!$J$3:$J$14,COLUMN()-11) | Q20: =INDEX('Ref'!$J$3:$J$14,COLUMN()-11) | R20: =INDEX('Ref'!$J$3:$J$14,COLUMN()-11) | S20: =INDEX('Ref'!$J$3:$J$14,COLUMN()-11) | ... W20: =INDEX('Ref'!$J$3:$J$14,COLUMN()-11) | Z20: Notes / source
A21: Airline credit | B21: SC | C21: SEMI-ANNUAL | D21: 50 | E21: =IF($C21="MONTHLY",12,IF($C21="QUARTERLY",4,IF($C21="SEMI-ANNUAL",2,IF($C21="CALENDAR-YEAR",1,"")))) | F21: =IF(OR($D21="",$E21=""),"",$D21*$E21) | G21: =IF($D21="","",IF(ISNUMBER($F21),MIN($X21,$F21),$X21)) | H21: =IF($F21="","",MAX(0,$F21-$G21)) | I21: =SUMPRODUCT(ISNUMBER($L21:$W21)*($L21:$W21>0)) | J21: =IF($C21="MONTHLY",EOMONTH(TODAY(),0),IF($C21="QUARTERLY",EOMONTH(DATE('Ref'!$B$1,ROUNDUP(MONTH(TODAY())/3,0)*3,1),0),IF($C21="SEMI-ANNUAL",IF(MONTH(TODAY())<=6,DATE('Ref'!$B$1,6,30),DATE('Ref'!$B$1,12,31)),DATE('Ref'!$B$1,12,31)))) | K21: =IFERROR($J21-TODAY(),"") | X21: =IF($D21="",SUM($L21:$W21),SUM($L21:$W21)-SUMIF($L21:$W21,">"&$D21)+(COUNT($L21:$W21)-COUNTIF($L21:$W21,"<="&$D21))*$D21) | Y21: =IF(AND(ISNUMBER($H21),$H21>0,ISNUMBER($K21),$K21>=0),$K21,9999) | Z21: OFFICIAL (Chase.com): 'Unlock up to $100 in Airline Credits' - a $50 statement credit after you spend $250 or more DIRECTLY WITH AIRLINES in Jan-Jun, and another $50 after $250 or more in Jul-Dec (max $100 through 12/31/2026). EXISTING cardmembers must activate the offer once at chase.com/mybonus/marriott-airline-credit or by phone. New cardmembers who applied 6/4/2026-12/31/2026 are auto-enrolled and their second half runs Jan-Jun 2027
A22: Subtotal - Section 1 | F22: =SUM($F$21:$F$21) | G22: =SUM($G$21:$G$21) | H22: =SUM($H$21:$H$21) | I22: =SUM($I$21:$I$21)
A24: SECTION 2 · ESTIMATED SAVINGS (EST) · Counts only in the 'incl. estimated' totals.
A25: Benefit | B25: Basis | C25: Cycle | D25: Value/cycle | E25: Cyc/yr | F25: Max annual | G25: Used | H25: Remaining | I25: Uses | J25: Cycle end | K25: Days left | L25: =INDEX('Ref'!$J$3:$J$14,COLUMN()-11) | M25: =INDEX('Ref'!$J$3:$J$14,COLUMN()-11) | N25: =INDEX('Ref'!$J$3:$J$14,COLUMN()-11) | O25: =INDEX('Ref'!$J$3:$J$14,COLUMN()-11) | P25: =INDEX('Ref'!$J$3:$J$14,COLUMN()-11) | Q25: =INDEX('Ref'!$J$3:$J$14,COLUMN()-11) | R25: =INDEX('Ref'!$J$3:$J$14,COLUMN()-11) | S25: =INDEX('Ref'!$J$3:$J$14,COLUMN()-11) | ... W25: =INDEX('Ref'!$J$3:$J$14,COLUMN()-11) | Z25: Notes / source
A26: DoorDash non-restaurant discount | B26: EST | C26: QUARTERLY | D26: 10 | E26: =IF($C26="MONTHLY",12,IF($C26="QUARTERLY",4,IF($C26="SEMI-ANNUAL",2,IF($C26="CALENDAR-YEAR",1,"")))) | F26: =IF(OR($D26="",$E26=""),"",$D26*$E26) | G26: =IF($D26="","",IF(ISNUMBER($F26),MIN($X26,$F26),$X26)) | H26: =IF($F26="","",MAX(0,$F26-$G26)) | I26: =SUMPRODUCT(ISNUMBER($L26:$W26)*($L26:$W26>0)) | J26: =IF($C26="MONTHLY",EOMONTH(TODAY(),0),IF($C26="QUARTERLY",EOMONTH(DATE('Ref'!$B$1,ROUNDUP(MONTH(TODAY())/3,0)*3,1),0),IF($C26="SEMI-ANNUAL",IF(MONTH(TODAY())<=6,DATE('Ref'!$B$1,6,30),DATE('Ref'!$B$1,12,31)),DATE('Ref'!$B$1,12,31)))) | K26: =IFERROR($J26-TODAY(),"") | X26: =IF($D26="",SUM($L26:$W26),SUM($L26:$W26)-SUMIF($L26:$W26,">"&$D26)+(COUNT($L26:$W26)-COUNTIF($L26:$W26,"<="&$D26))*$D26) | Y26: =IF(AND(ISNUMBER($H26),$H26>0,ISNUMBER($K26),$K26>=0),$K26,9999) | Z26: OFFICIAL (Chase.com): $10 off one qualifying non-restaurant DoorDash order each calendar quarter (up to $40/yr) once you activate the complimentary DashPass. It is a checkout discount, not a statement credit, hence EST
A27: Subtotal - Section 2 | F27: =SUM($F$26:$F$26) | G27: =SUM($G$26:$G$26) | H27: =SUM($H$26:$H$26) | I27: =SUM($I$26:$I$26)
A29: SECTION 2b · ESTIMATED SAVINGS (EST) THAT RESET ON YOUR CARD ANNIVERSARY · the month columns follow YOUR anniversary month, not January. Counts only in the 'incl. estimated' totals.
A30: Benefit | B30: Basis | C30: Cycle | D30: Value/cycle | E30: Cyc/yr | F30: Max annual | G30: Used | H30: Remaining | I30: Uses | J30: Cycle end | K30: Days left | L30: =IFERROR(INDEX('Ref'!$J$3:$J$14,MONTH(EDATE($B$14,0)))&"-"&TEXT(EDATE($B$14,0),"yy"),"") | M30: =IFERROR(INDEX('Ref'!$J$3:$J$14,MONTH(EDATE($B$14,1)))&"-"&TEXT(EDATE($B$14,1),"yy"),"") | N30: =IFERROR(INDEX('Ref'!$J$3:$J$14,MONTH(EDATE($B$14,2)))&"-"&TEXT(EDATE($B$14,2),"yy"),"") | O30: =IFERROR(INDEX('Ref'!$J$3:$J$14,MONTH(EDATE($B$14,3)))&"-"&TEXT(EDATE($B$14,3),"yy"),"") | P30: =IFERROR(INDEX('Ref'!$J$3:$J$14,MONTH(EDATE($B$14,4)))&"-"&TEXT(EDATE($B$14,4),"yy"),"") | Q30: =IFERROR(INDEX('Ref'!$J$3:$J$14,MONTH(EDATE($B$14,5)))&"-"&TEXT(EDATE($B$14,5),"yy"),"") | R30: =IFERROR(INDEX('Ref'!$J$3:$J$14,MONTH(EDATE($B$14,6)))&"-"&TEXT(EDATE($B$14,6),"yy"),"") | S30: =IFERROR(INDEX('Ref'!$J$3:$J$14,MONTH(EDATE($B$14,7)))&"-"&TEXT(EDATE($B$14,7),"yy"),"") | T30: =IFERROR(INDEX('Ref'!$J$3:$J$14,MONTH(EDATE($B$14,8)))&"-"&TEXT(EDATE($B$14,8),"yy"),"") | U30: =IFERROR(INDEX('Ref'!$J$3:$J$14,MONTH(EDATE($B$14,9)))&"-"&TEXT(EDATE($B$14,9),"yy"),"") | V30: =IFERROR(INDEX('Ref'!$J$3:$J$14,MONTH(EDATE($B$14,10)))&"-"&TEXT(EDATE($B$14,10),"yy"),"") | W30: =IFERROR(INDEX('Ref'!$J$3:$J$14,MONTH(EDATE($B$14,11)))&"-"&TEXT(EDATE($B$14,11),"yy"),"") | Z30: Notes / source
A31: Annual Free Night Award | B31: EST | C31: CARDMEMBER-YEAR | E31: 1 | F31: =IF($D31="","",$D31) | G31: =IF($D31="","",IF(ISNUMBER($F31),MIN($X31,$F31),$X31)) | H31: =IF($F31="","",MAX(0,$F31-$G31)) | I31: =SUMPRODUCT(ISNUMBER($L31:$W31)*($L31:$W31>0)) | J31: =IFERROR(EDATE($B$14,12)-1,"") | K31: =IFERROR($J31-TODAY(),"") | X31: =IF($D31="",SUM($L31:$W31),SUM($L31:$W31)-SUMIF($L31:$W31,">"&$D31)+(COUNT($L31:$W31)-COUNTIF($L31:$W31,"<="&$D31))*$D31) | Y31: =IF(AND(ISNUMBER($H31),$H31>0,ISNUMBER($K31),$K31>=0),$K31,9999) | Z31: OFFICIAL (Chase.com): one free night each account anniversary year, valid at Marriott properties up to 35,000 points (you may top up with your own points). Deposited up to 8 weeks after the anniversary and expires 12 months later. NOT a statement credit - enter what the night would have cost you, or delete this row if you only want statement credits
A32: Subtotal - Section 2b | F32: =SUM($F$31:$F$31) | G32: =SUM($G$31:$G$31) | H32: =SUM($H$31:$H$31) | I32: =SUM($I$31:$I$31)

Sheet CHASE-CSP
A1: Card | B1: CHASE-CSP
A2: Issuer | B2: Chase | Z2: Annual fee $95. The June 2026 refresh applies automatically to existing cardmembers. Open date is a PLACEHOLDER - change B5 and B10.
A3: Product (exact) | B3: Chase Sapphire Preferred | D3: Credits used YTD - statement credits (SC) | E3: =SUMIF($B$21:$B$21,"SC",$G$21:$G$21)+SUMIF($B$26:$B$26,"SC",$G$26:$G$26)+SUMIFS($F$31:$F$31,$B$31:$B$31,"SC",$I$31:$I$31,"y") | G3: =HYPERLINK("#'Dashboard'!A1","< back to Dashboard") | H3: =MIN($Y$21:$Y$21,$Y$26:$Y$26)
A4: Card status | B4: Active | D4: Credits used YTD - incl. estimated (SC+EST) | E4: =SUMIF($B$21:$B$21,"SC",$G$21:$G$21)+SUMIF($B$26:$B$26,"SC",$G$26:$G$26)+SUMIFS($F$31:$F$31,$B$31:$B$31,"SC",$I$31:$I$31,"y")+SUMIF($B$21:$B$21,"EST",$G$21:$G$21)+SUMIF($B$26:$B$26,"EST",$G$26:$G$26)+SUMIFS($F$31:$F$31,$B$31:$B$31,"EST",$I$31:$I$31,"y") | H4: =SUMIF($B$21:$B$21,"SC",$F$21:$F$21)+SUMIF($B$26:$B$26,"SC",$F$26:$F$26)+SUMIFS($F$31:$F$31,$B$31:$B$31,"SC")
A5: Open date (approval) | B5: 46023 | D5: Max annual value (statement credits + estimated) | E5: =SUM($F$21:$F$21)+SUM($F$26:$F$26)+SUM($F$31:$F$31)
A6: Months held | B6: =IF($B$5="","",DATEDIF($B$5,TODAY(),"m")) | D6: Remaining annual credit value (incl. est.) | E6: =MAX(0,$E$5-$E$4)
A7: Years held | B7: =IF($B$6="","",ROUND($B$6/12,1)) | D7: Remaining - statement credits only | E7: =MAX(0,$H$4-$E$3)
A8: Annual fee (USD) | B8: 95 | D8: Net benefit - statement credits | E8: =$E$3-$B$12
A9: First-year AF waived? | D9: Net benefit - incl. estimated | E9: =$E$4-$B$12
A10: AF posting date (current cycle) | B10: 46023 | D10: Result | E10: =IF($E$8>=0,"POSITIVE","NEGATIVE")
A11: Authorized user AF (total, USD) | B11: 0 | D11: AF breakeven gap | E11: =MAX(0,-$E$8)
A12: Total AF charged (this cycle) | B12: =IF($B$9="y",0,$B$8)+$B$11 | D12: Credit utilization % | E12: =IF($E$5=0,"",$E$4/$E$5)
A13: Next AF date (projected) | B13: =EDATE($B$10,12) | D13: Credits at risk (unused, <=30 days left) | E13: =SUMPRODUCT(($Y$21:$Y$21>=0)*($Y$21:$Y$21<=30))+SUMPRODUCT(($Y$26:$Y$26>=0)*($Y$26:$Y$26<=30))
A14: Cardmember year start (current cycle) | B14: =IFERROR(EDATE($B$10,12*DATEDIF($B$10,TODAY(),"y")),"") | D14: Nearest expiry (days) | E14: =IF($H$3>=9999,"",$H$3)
D15: Amounts you entered (cells) | E15: =COUNT(L21:W21)+COUNT(L26:W26)+COUNTIF($I$31:$I$31,">0")
D16: Entered total before capping | E16: =SUM(L21:W21)+SUM(L26:W26)+SUM($J$31:$J$31)
A17: WHERE TO TYPE: put the amount you used into the month column of that row. SC rows are real statement credits and drive your net benefit. EST rows are values you set yourself (baggage fees saved) and only count in the 'incl. estimated' totals. 'Amounts you entered' above counts how many month cells you have filled in.
A19: SECTION 1 · STATEMENT CREDITS (SC) · real money on your statement. NET BENEFIT COMES FROM HERE. Type the amount you used into the month column.
A20: Benefit | B20: Basis | C20: Cycle | D20: Value/cycle | E20: Cyc/yr | F20: Max annual | G20: Used | H20: Remaining | I20: Uses | J20: Cycle end | K20: Days left | L20: =INDEX('Ref'!$J$3:$J$14,COLUMN()-11) | M20: =INDEX('Ref'!$J$3:$J$14,COLUMN()-11) | N20: =INDEX('Ref'!$J$3:$J$14,COLUMN()-11) | O20: =INDEX('Ref'!$J$3:$J$14,COLUMN()-11) | P20: =INDEX('Ref'!$J$3:$J$14,COLUMN()-11) | Q20: =INDEX('Ref'!$J$3:$J$14,COLUMN()-11) | R20: =INDEX('Ref'!$J$3:$J$14,COLUMN()-11) | S20: =INDEX('Ref'!$J$3:$J$14,COLUMN()-11) | ... W20: =INDEX('Ref'!$J$3:$J$14,COLUMN()-11) | Z20: Notes / source
A21: DoorDash non-restaurant credit | B21: SC | C21: MONTHLY | D21: 10 | E21: =IF($C21="MONTHLY",12,IF($C21="QUARTERLY",4,IF($C21="SEMI-ANNUAL",2,IF($C21="CALENDAR-YEAR",1,"")))) | F21: =IF(OR($D21="",$E21=""),"",$D21*$E21) | G21: =IF($D21="","",IF(ISNUMBER($F21),MIN($X21,$F21),$X21)) | H21: =IF($F21="","",MAX(0,$F21-$G21)) | I21: =SUMPRODUCT(ISNUMBER($L21:$W21)*($L21:$W21>0)) | J21: =IF($C21="MONTHLY",EOMONTH(TODAY(),0),IF($C21="QUARTERLY",EOMONTH(DATE('Ref'!$B$1,ROUNDUP(MONTH(TODAY())/3,0)*3,1),0),IF($C21="SEMI-ANNUAL",IF(MONTH(TODAY())<=6,DATE('Ref'!$B$1,6,30),DATE('Ref'!$B$1,12,31)),DATE('Ref'!$B$1,12,31)))) | K21: =IFERROR($J21-TODAY(),"") | X21: =IF($D21="",SUM($L21:$W21),SUM($L21:$W21)-SUMIF($L21:$W21,">"&$D21)+(COUNT($L21:$W21)-COUNTIF($L21:$W21,"<="&$D21))*$D21) | Y21: =IF(AND(ISNUMBER($H21),$H21>0,ISNUMBER($K21),$K21>=0),$K21,9999) | Z21: $10/mo promo through 12/31/2027; requires DashPass activated
A22: Subtotal - Section 1 | F22: =SUM($F$21:$F$21) | G22: =SUM($G$21:$G$21) | H22: =SUM($H$21:$H$21) | I22: =SUM($I$21:$I$21)
A24: SECTION 1b · STATEMENT CREDITS (SC) THAT RESET ON YOUR CARD ANNIVERSARY · the month columns follow YOUR anniversary month, not January. NET BENEFIT COMES FROM HERE.
A25: Benefit | B25: Basis | C25: Cycle | D25: Value/cycle | E25: Cyc/yr | F25: Max annual | G25: Used | H25: Remaining | I25: Uses | J25: Cycle end | K25: Days left | L25: =IFERROR(INDEX('Ref'!$J$3:$J$14,MONTH(EDATE($B$14,0)))&"-"&TEXT(EDATE($B$14,0),"yy"),"") | M25: =IFERROR(INDEX('Ref'!$J$3:$J$14,MONTH(EDATE($B$14,1)))&"-"&TEXT(EDATE($B$14,1),"yy"),"") | N25: =IFERROR(INDEX('Ref'!$J$3:$J$14,MONTH(EDATE($B$14,2)))&"-"&TEXT(EDATE($B$14,2),"yy"),"") | O25: =IFERROR(INDEX('Ref'!$J$3:$J$14,MONTH(EDATE($B$14,3)))&"-"&TEXT(EDATE($B$14,3),"yy"),"") | P25: =IFERROR(INDEX('Ref'!$J$3:$J$14,MONTH(EDATE($B$14,4)))&"-"&TEXT(EDATE($B$14,4),"yy"),"") | Q25: =IFERROR(INDEX('Ref'!$J$3:$J$14,MONTH(EDATE($B$14,5)))&"-"&TEXT(EDATE($B$14,5),"yy"),"") | R25: =IFERROR(INDEX('Ref'!$J$3:$J$14,MONTH(EDATE($B$14,6)))&"-"&TEXT(EDATE($B$14,6),"yy"),"") | S25: =IFERROR(INDEX('Ref'!$J$3:$J$14,MONTH(EDATE($B$14,7)))&"-"&TEXT(EDATE($B$14,7),"yy"),"") | T25: =IFERROR(INDEX('Ref'!$J$3:$J$14,MONTH(EDATE($B$14,8)))&"-"&TEXT(EDATE($B$14,8),"yy"),"") | U25: =IFERROR(INDEX('Ref'!$J$3:$J$14,MONTH(EDATE($B$14,9)))&"-"&TEXT(EDATE($B$14,9),"yy"),"") | V25: =IFERROR(INDEX('Ref'!$J$3:$J$14,MONTH(EDATE($B$14,10)))&"-"&TEXT(EDATE($B$14,10),"yy"),"") | W25: =IFERROR(INDEX('Ref'!$J$3:$J$14,MONTH(EDATE($B$14,11)))&"-"&TEXT(EDATE($B$14,11),"yy"),"") | Z25: Notes / source
A26: Chase Travel hotel credit | B26: SC | C26: CARDMEMBER-YEAR | D26: 100 | E26: 1 | F26: =IF($D26="","",$D26) | G26: =IF($D26="","",IF(ISNUMBER($F26),MIN($X26,$F26),$X26)) | H26: =IF($F26="","",MAX(0,$F26-$G26)) | I26: =SUMPRODUCT(ISNUMBER($L26:$W26)*($L26:$W26>0)) | J26: =IFERROR(EDATE($B$14,12)-1,"") | K26: =IFERROR($J26-TODAY(),"") | X26: =IF($D26="",SUM($L26:$W26),SUM($L26:$W26)-SUMIF($L26:$W26,">"&$D26)+(COUNT($L26:$W26)-COUNTIF($L26:$W26,"<="&$D26))*$D26) | Y26: =IF(AND(ISNUMBER($H26),$H26>0,ISNUMBER($K26),$K26>=0),$K26,9999) | Z26: OFFICIAL (Chase.com): '$100 Annual Chase Travel Hotel Credit' - resets every year on the cardmember's anniversary and unused amounts are forfeited. Prepaid hotels booked through Chase Travel only. No activation needed
A27: Subtotal - Section 1b | F27: =SUM($F$26:$F$26) | G27: =SUM($G$26:$G$26) | H27: =SUM($H$26:$H$26) | I27: =SUM($I$26:$I$26)
A29: SECTION 4 · ONE-TIME / EVERY-N-YEARS ITEMS (SC) · no month grid - enter the amount in the 'Used?' column.
A30: Benefit | B30: Basis | C30: Cycle | D30: Value | E30: Yrs/cycle | F30: Annualized | G30: Date used | H30: Expiry / next eligible | I30: Used? (amount or y) | J30: Value captured | K30: Notes
A31: Global Entry / TSA PreCheck / NEXUS credit | B31: SC | C31: MULTI-YEAR | D31: 120 | E31: 4 | F31: =IF(AND(ISNUMBER($D31),ISNUMBER($E31)),$D31/$E31,0) | J31: =IF($I31="y",$D31,IF(ISNUMBER($I31),MIN($I31,$D31),0)) | K31: OFFICIAL (Chase press release 2026-06-15): '$120 Global Entry, TSA PreCheck, or NEXUS credit every four years'. Added 2026-06-15, no activation needed. Enter the amount in the 'Used?' column when you claim it
A32: Subtotal - Section 4 | D32: =SUM($D$31:$D$31) | F32: =SUM($F$31:$F$31) | J32: =SUM($J$31:$J$31)

Sheet TEMPLATE
A1: Card
A2: Issuer
A3: Product (exact) | D3: Credits used YTD - statement credits (SC) | E3: =SUMIF($B$21:$B$22,"SC",$G$21:$G$22)+SUMIF($B$27:$B$27,"SC",$G$27:$G$27)+SUMIF($B$32:$B$32,"SC",$G$32:$G$32)+SUMIF($B$37:$B$37,"SC",$G$37:$G$37)+SUMIFS($F$42:$F$42,$B$42:$B$42,"SC",$I$42:$I$42,"y")+SUMIFS($F$47:$F$47,$B$47:$B$47,"SC",$I$47:$I$47,"y") | G3: =HYPERLINK("#'Dashboard'!A1","< back to Dashboard") | H3: =MIN($Y$21:$Y$22,$Y$27:$Y$27,$Y$32:$Y$32,$Y$37:$Y$37)
A4: Card status | D4: Credits used YTD - incl. estimated (SC+EST) | E4: =SUMIF($B$21:$B$22,"SC",$G$21:$G$22)+SUMIF($B$27:$B$27,"SC",$G$27:$G$27)+SUMIF($B$32:$B$32,"SC",$G$32:$G$32)+SUMIF($B$37:$B$37,"SC",$G$37:$G$37)+SUMIFS($F$42:$F$42,$B$42:$B$42,"SC",$I$42:$I$42,"y")+SUMIFS($F$47:$F$47,$B$47:$B$47,"SC",$I$47:$I$47,"y")+SUMIF($B$21:$B$22,"EST",$G$21:$G$22)+SUMIF($B$27:$B$27,"EST",$G$27:$G$27)+SUMIF($B$32:$B$32,"EST",$G$32:$G$32)+SUMIF($B$37:$B$37,"EST",$G$37:$G$37)+SUMIFS($F$42:$F$42,$B$42:$B$42,"EST",$I$42:$I$42,"y")+SUMIFS($F$47:$F$47,$B$47:$B$47,"EST",$I$47:$I$47,"y") | H4: =SUMIF($B$21:$B$22,"SC",$F$21:$F$22)+SUMIF($B$27:$B$27,"SC",$F$27:$F$27)+SUMIF($B$32:$B$32,"SC",$F$32:$F$32)+SUMIF($B$37:$B$37,"SC",$F$37:$F$37)+SUMIFS($F$42:$F$42,$B$42:$B$42,"SC")+SUMIFS($F$47:$F$47,$B$47:$B$47,"SC")
A5: Open date (approval) | D5: Max annual value (statement credits + estimated) | E5: =SUM($F$21:$F$22)+SUM($F$27:$F$27)+SUM($F$32:$F$32)+SUM($F$37:$F$37)+SUM($F$42:$F$42)+SUM($F$47:$F$47)
A6: Months held | B6: =IF($B$5="","",DATEDIF($B$5,TODAY(),"m")) | D6: Remaining annual credit value (incl. est.) | E6: =MAX(0,$E$5-$E$4)
A7: Years held | B7: =IF($B$6="","",ROUND($B$6/12,1)) | D7: Remaining - statement credits only | E7: =MAX(0,$H$4-$E$3)
A8: Annual fee (USD) | D8: Net benefit - statement credits | E8: =$E$3-$B$12
A9: First-year AF waived? | D9: Net benefit - incl. estimated | E9: =$E$4-$B$12
A10: AF posting date (current cycle) | D10: Result | E10: =IF($E$8>=0,"POSITIVE","NEGATIVE")
A11: Authorized user AF (total, USD) | D11: AF breakeven gap | E11: =MAX(0,-$E$8)
A12: Total AF charged (this cycle) | B12: =IF($B$9="y",0,$B$8)+$B$11 | D12: Credit utilization % | E12: =IF($E$5=0,"",$E$4/$E$5)
A13: Next AF date (projected) | B13: =EDATE($B$10,12) | D13: Credits at risk (unused, <=30 days left) | E13: =SUMPRODUCT(($Y$21:$Y$22>=0)*($Y$21:$Y$22<=30))+SUMPRODUCT(($Y$27:$Y$27>=0)*($Y$27:$Y$27<=30))+SUMPRODUCT(($Y$32:$Y$32>=0)*($Y$32:$Y$32<=30))+SUMPRODUCT(($Y$37:$Y$37>=0)*($Y$37:$Y$37<=30))
A14: Cardmember year start (current cycle) | B14: =IFERROR(EDATE($B$10,12*DATEDIF($B$10,TODAY(),"y")),"") | D14: Nearest expiry (days) | E14: =IF($H$3>=9999,"",$H$3)
D15: Amounts you entered (cells) | E15: =COUNT(L21:W22)+COUNT(L27:W27)+COUNT(L32:W32)+COUNT(L37:W37)+COUNTIF($I$42:$I$42,">0")+COUNTIF($I$47:$I$47,">0")
D16: Entered total before capping | E16: =SUM(L21:W22)+SUM(L27:W27)+SUM(L32:W32)+SUM(L37:W37)+SUM($J$42:$J$42)+SUM($J$47:$J$47)
A17: WHERE TO TYPE: put the amount you used into the month column of that row. SC rows are real statement credits and drive your net benefit. EST rows are values you set yourself (baggage fees saved) and only count in the 'incl. estimated' totals. 'Amounts you entered' above counts how many month cells you have filled in.
A19: SECTION 1 · STATEMENT CREDITS (SC) · real money on your statement. NET BENEFIT COMES FROM HERE. Type the amount you used into the month column.
A20: Benefit | B20: Basis | C20: Cycle | D20: Value/cycle | E20: Cyc/yr | F20: Max annual | G20: Used | H20: Remaining | I20: Uses | J20: Cycle end | K20: Days left | L20: =INDEX('Ref'!$J$3:$J$14,COLUMN()-11) | M20: =INDEX('Ref'!$J$3:$J$14,COLUMN()-11) | N20: =INDEX('Ref'!$J$3:$J$14,COLUMN()-11) | O20: =INDEX('Ref'!$J$3:$J$14,COLUMN()-11) | P20: =INDEX('Ref'!$J$3:$J$14,COLUMN()-11) | Q20: =INDEX('Ref'!$J$3:$J$14,COLUMN()-11) | R20: =INDEX('Ref'!$J$3:$J$14,COLUMN()-11) | S20: =INDEX('Ref'!$J$3:$J$14,COLUMN()-11) | ... W20: =INDEX('Ref'!$J$3:$J$14,COLUMN()-11) | Z20: Notes / source
A21: (example) Monthly credit | B21: SC | C21: MONTHLY | D21: 10 | E21: =IF($C21="MONTHLY",12,IF($C21="QUARTERLY",4,IF($C21="SEMI-ANNUAL",2,IF($C21="CALENDAR-YEAR",1,"")))) | F21: =IF(OR($D21="",$E21=""),"",$D21*$E21) | G21: =IF($D21="","",IF(ISNUMBER($F21),MIN($X21,$F21),$X21)) | H21: =IF($F21="","",MAX(0,$F21-$G21)) | I21: =SUMPRODUCT(ISNUMBER($L21:$W21)*($L21:$W21>0)) | J21: =IF($C21="MONTHLY",EOMONTH(TODAY(),0),IF($C21="QUARTERLY",EOMONTH(DATE('Ref'!$B$1,ROUNDUP(MONTH(TODAY())/3,0)*3,1),0),IF($C21="SEMI-ANNUAL",IF(MONTH(TODAY())<=6,DATE('Ref'!$B$1,6,30),DATE('Ref'!$B$1,12,31)),DATE('Ref'!$B$1,12,31)))) | K21: =IFERROR($J21-TODAY(),"") | X21: =IF($D21="",SUM($L21:$W21),SUM($L21:$W21)-SUMIF($L21:$W21,">"&$D21)+(COUNT($L21:$W21)-COUNTIF($L21:$W21,"<="&$D21))*$D21) | Y21: =IF(AND(ISNUMBER($H21),$H21>0,ISNUMBER($K21),$K21>=0),$K21,9999) | Z21: Replace or delete this row
A22: (example) Annual statement credit | B22: SC | C22: CALENDAR-YEAR | D22: 100 | E22: =IF($C22="MONTHLY",12,IF($C22="QUARTERLY",4,IF($C22="SEMI-ANNUAL",2,IF($C22="CALENDAR-YEAR",1,"")))) | F22: =IF(OR($D22="",$E22=""),"",$D22*$E22) | G22: =IF($D22="","",IF(ISNUMBER($F22),MIN($X22,$F22),$X22)) | H22: =IF($F22="","",MAX(0,$F22-$G22)) | I22: =SUMPRODUCT(ISNUMBER($L22:$W22)*($L22:$W22>0)) | J22: =IF($C22="MONTHLY",EOMONTH(TODAY(),0),IF($C22="QUARTERLY",EOMONTH(DATE('Ref'!$B$1,ROUNDUP(MONTH(TODAY())/3,0)*3,1),0),IF($C22="SEMI-ANNUAL",IF(MONTH(TODAY())<=6,DATE('Ref'!$B$1,6,30),DATE('Ref'!$B$1,12,31)),DATE('Ref'!$B$1,12,31)))) | K22: =IFERROR($J22-TODAY(),"") | X22: =IF($D22="",SUM($L22:$W22),SUM($L22:$W22)-SUMIF($L22:$W22,">"&$D22)+(COUNT($L22:$W22)-COUNTIF($L22:$W22,"<="&$D22))*$D22) | Y22: =IF(AND(ISNUMBER($H22),$H22>0,ISNUMBER($K22),$K22>=0),$K22,9999) | Z22: Replace or delete this row
A23: Subtotal - Section 1 | F23: =SUM($F$21:$F$22) | G23: =SUM($G$21:$G$22) | H23: =SUM($H$21:$H$22) | I23: =SUM($I$21:$I$22)
A25: SECTION 1b · STATEMENT CREDITS (SC) THAT RESET ON YOUR CARD ANNIVERSARY · the month columns follow YOUR anniversary month, not January. NET BENEFIT COMES FROM HERE.
A26: Benefit | B26: Basis | C26: Cycle | D26: Value/cycle | E26: Cyc/yr | F26: Max annual | G26: Used | H26: Remaining | I26: Uses | J26: Cycle end | K26: Days left | L26: =IFERROR(INDEX('Ref'!$J$3:$J$14,MONTH(EDATE($B$14,0)))&"-"&TEXT(EDATE($B$14,0),"yy"),"") | M26: =IFERROR(INDEX('Ref'!$J$3:$J$14,MONTH(EDATE($B$14,1)))&"-"&TEXT(EDATE($B$14,1),"yy"),"") | N26: =IFERROR(INDEX('Ref'!$J$3:$J$14,MONTH(EDATE($B$14,2)))&"-"&TEXT(EDATE($B$14,2),"yy"),"") | O26: =IFERROR(INDEX('Ref'!$J$3:$J$14,MONTH(EDATE($B$14,3)))&"-"&TEXT(EDATE($B$14,3),"yy"),"") | P26: =IFERROR(INDEX('Ref'!$J$3:$J$14,MONTH(EDATE($B$14,4)))&"-"&TEXT(EDATE($B$14,4),"yy"),"") | Q26: =IFERROR(INDEX('Ref'!$J$3:$J$14,MONTH(EDATE($B$14,5)))&"-"&TEXT(EDATE($B$14,5),"yy"),"") | R26: =IFERROR(INDEX('Ref'!$J$3:$J$14,MONTH(EDATE($B$14,6)))&"-"&TEXT(EDATE($B$14,6),"yy"),"") | S26: =IFERROR(INDEX('Ref'!$J$3:$J$14,MONTH(EDATE($B$14,7)))&"-"&TEXT(EDATE($B$14,7),"yy"),"") | T26: =IFERROR(INDEX('Ref'!$J$3:$J$14,MONTH(EDATE($B$14,8)))&"-"&TEXT(EDATE($B$14,8),"yy"),"") | U26: =IFERROR(INDEX('Ref'!$J$3:$J$14,MONTH(EDATE($B$14,9)))&"-"&TEXT(EDATE($B$14,9),"yy"),"") | V26: =IFERROR(INDEX('Ref'!$J$3:$J$14,MONTH(EDATE($B$14,10)))&"-"&TEXT(EDATE($B$14,10),"yy"),"") | W26: =IFERROR(INDEX('Ref'!$J$3:$J$14,MONTH(EDATE($B$14,11)))&"-"&TEXT(EDATE($B$14,11),"yy"),"") | Z26: Notes / source
A27: (example) Credit that resets on your card anniversary | B27: SC | C27: CARDMEMBER-YEAR | D27: 100 | E27: 1 | F27: =IF($D27="","",$D27) | G27: =IF($D27="","",IF(ISNUMBER($F27),MIN($X27,$F27),$X27)) | H27: =IF($F27="","",MAX(0,$F27-$G27)) | I27: =SUMPRODUCT(ISNUMBER($L27:$W27)*($L27:$W27>0)) | J27: =IFERROR(EDATE($B$14,12)-1,"") | K27: =IFERROR($J27-TODAY(),"") | X27: =IF($D27="",SUM($L27:$W27),SUM($L27:$W27)-SUMIF($L27:$W27,">"&$D27)+(COUNT($L27:$W27)-COUNTIF($L27:$W27,"<="&$D27))*$D27) | Y27: =IF(AND(ISNUMBER($H27),$H27>0,ISNUMBER($K27),$K27>=0),$K27,9999) | Z27: Lives in the anniversary section; the month columns follow B14
A28: Subtotal - Section 1b | F28: =SUM($F$27:$F$27) | G28: =SUM($G$27:$G$27) | H28: =SUM($H$27:$H$27) | I28: =SUM($I$27:$I$27)
A30: SECTION 2 · ESTIMATED SAVINGS (EST) · Counts only in the 'incl. estimated' totals.
A31: Benefit | B31: Basis | C31: Cycle | D31: Value/cycle | E31: Cyc/yr | F31: Max annual | G31: Used | H31: Remaining | I31: Uses | J31: Cycle end | K31: Days left | L31: =INDEX('Ref'!$J$3:$J$14,COLUMN()-11) | M31: =INDEX('Ref'!$J$3:$J$14,COLUMN()-11) | N31: =INDEX('Ref'!$J$3:$J$14,COLUMN()-11) | O31: =INDEX('Ref'!$J$3:$J$14,COLUMN()-11) | P31: =INDEX('Ref'!$J$3:$J$14,COLUMN()-11) | Q31: =INDEX('Ref'!$J$3:$J$14,COLUMN()-11) | R31: =INDEX('Ref'!$J$3:$J$14,COLUMN()-11) | S31: =INDEX('Ref'!$J$3:$J$14,COLUMN()-11) | ... W31: =INDEX('Ref'!$J$3:$J$14,COLUMN()-11) | Z31: Notes / source
A32: (example) Estimated perk value | B32: EST | C32: CALENDAR-YEAR | E32: =IF($C32="MONTHLY",12,IF($C32="QUARTERLY",4,IF($C32="SEMI-ANNUAL",2,IF($C32="CALENDAR-YEAR",1,"")))) | F32: =IF(OR($D32="",$E32=""),"",$D32*$E32) | G32: =IF($D32="","",IF(ISNUMBER($F32),MIN($X32,$F32),$X32)) | H32: =IF($F32="","",MAX(0,$F32-$G32)) | I32: =SUMPRODUCT(ISNUMBER($L32:$W32)*($L32:$W32>0)) | J32: =IF($C32="MONTHLY",EOMONTH(TODAY(),0),IF($C32="QUARTERLY",EOMONTH(DATE('Ref'!$B$1,ROUNDUP(MONTH(TODAY())/3,0)*3,1),0),IF($C32="SEMI-ANNUAL",IF(MONTH(TODAY())<=6,DATE('Ref'!$B$1,6,30),DATE('Ref'!$B$1,12,31)),DATE('Ref'!$B$1,12,31)))) | K32: =IFERROR($J32-TODAY(),"") | X32: =IF($D32="",SUM($L32:$W32),SUM($L32:$W32)-SUMIF($L32:$W32,">"&$D32)+(COUNT($L32:$W32)-COUNTIF($L32:$W32,"<="&$D32))*$D32) | Y32: =IF(AND(ISNUMBER($H32),$H32>0,ISNUMBER($K32),$K32>=0),$K32,9999) | Z32: EST rows count only in the incl.-estimated totals
A33: Subtotal - Section 2 | F33: =SUM($F$32:$F$32) | G33: =SUM($G$32:$G$32) | H33: =SUM($H$32:$H$32) | I33: =SUM($I$32:$I$32)
A35: SECTION 3 · ACCESS PERKS (no dollar value) · A number typed here logs a USE only and never adds dollars.
A36: Benefit | B36: Basis | C36: Cycle | D36: Value/cycle | E36: Cyc/yr | F36: Max annual | G36: Used | H36: Remaining | I36: Uses | J36: Cycle end | K36: Days left | L36: =INDEX('Ref'!$J$3:$J$14,COLUMN()-11) | M36: =INDEX('Ref'!$J$3:$J$14,COLUMN()-11) | N36: =INDEX('Ref'!$J$3:$J$14,COLUMN()-11) | O36: =INDEX('Ref'!$J$3:$J$14,COLUMN()-11) | P36: =INDEX('Ref'!$J$3:$J$14,COLUMN()-11) | Q36: =INDEX('Ref'!$J$3:$J$14,COLUMN()-11) | R36: =INDEX('Ref'!$J$3:$J$14,COLUMN()-11) | S36: =INDEX('Ref'!$J$3:$J$14,COLUMN()-11) | ... W36: =INDEX('Ref'!$J$3:$J$14,COLUMN()-11) | Z36: Notes / source
A37: (example) Free checked bag | B37: ACCESS | C37: MONTHLY | E37: =IF($C37="MONTHLY",12,IF($C37="QUARTERLY",4,IF($C37="SEMI-ANNUAL",2,IF($C37="CALENDAR-YEAR",1,"")))) | F37: =IF(OR($D37="",$E37=""),"",$D37*$E37) | G37: =IF($D37="","",IF(ISNUMBER($F37),MIN($X37,$F37),$X37)) | H37: =IF($F37="","",MAX(0,$F37-$G37)) | I37: =SUMPRODUCT(ISNUMBER($L37:$W37)*($L37:$W37>0)) | J37: =IF($C37="MONTHLY",EOMONTH(TODAY(),0),IF($C37="QUARTERLY",EOMONTH(DATE('Ref'!$B$1,ROUNDUP(MONTH(TODAY())/3,0)*3,1),0),IF($C37="SEMI-ANNUAL",IF(MONTH(TODAY())<=6,DATE('Ref'!$B$1,6,30),DATE('Ref'!$B$1,12,31)),DATE('Ref'!$B$1,12,31)))) | K37: =IFERROR($J37-TODAY(),"") | X37: =IF($D37="",SUM($L37:$W37),SUM($L37:$W37)-SUMIF($L37:$W37,">"&$D37)+(COUNT($L37:$W37)-COUNTIF($L37:$W37,"<="&$D37))*$D37) | Y37: =IF(AND(ISNUMBER($H37),$H37>0,ISNUMBER($K37),$K37>=0),$K37,9999) | Z37: ACCESS: a number here logs a use, never dollars
A38: Subtotal - Section 3 | F38: =SUM($F$37:$F$37) | G38: =SUM($G$37:$G$37) | H38: =SUM($H$37:$H$37) | I38: =SUM($I$37:$I$37)
A40: SECTION 4 · ONE-TIME / EVERY-N-YEARS ITEMS (SC) · no month grid - enter the amount in the 'Used?' column.
A41: Benefit | B41: Basis | C41: Cycle | D41: Value | E41: Yrs/cycle | F41: Annualized | G41: Date used | H41: Expiry / next eligible | I41: Used? (amount or y) | J41: Value captured | K41: Notes
A42: (example) Global Entry / TSA credit | B42: SC | C42: MULTI-YEAR | D42: 120 | E42: 4 | F42: =IF(AND(ISNUMBER($D42),ISNUMBER($E42)),$D42/$E42,0) | J42: =IF($I42="y",$D42,IF(ISNUMBER($I42),MIN($I42,$D42),0)) | K42: Every 4 years
A43: Subtotal - Section 4 | D43: =SUM($D$42:$D$42) | F43: =SUM($F$42:$F$42) | J43: =SUM($J$42:$J$42)
A45: SECTION 4b · ONE-TIME / EVERY-N-YEARS ITEMS (EST) · no month grid - enter the amount in the 'Used?' column.
A46: Benefit | B46: Basis | C46: Cycle | D46: Value | E46: Yrs/cycle | F46: Annualized | G46: Date used | H46: Expiry / next eligible | I46: Used? (amount or y) | J46: Value captured | K46: Notes
...

Sheet Ref
A1: Tracking year | B1: 2026 | J1: Short month names (English)
A2: Issuers
A3: Amex | J3: Jan
A4: Chase | J4: Feb
A5: Citi | J5: Mar
A6: Capital One | J6: Apr
A7: Bank of America | J7: May
A8: Discover | J8: Jun
A9: Wells Fargo | J9: Jul
A10: US Bank | J10: Aug
A11: Barclays | J11: Sep
A12: Robinhood | J12: Oct
A13: Other | J13: Nov
J14: Dec
A15: Basis
A16: SC
A17: EST
A18: ACCESS
A21: Cycles
A22: MONTHLY
A23: QUARTERLY
A24: SEMI-ANNUAL
A25: CALENDAR-YEAR
A26: CARDMEMBER-YEAR
A27: MULTI-YEAR
A28: ONE-TIME
... A36: Benefit catalog - typical reset cycles. Verify every amount on the issuer's own terms before relying on it.
A37: Benefit type | B37: Typical cycle | C37: Typical value | D37: Verification status
A38: Hilton Resort Credit (Aspire) | B38: SEMI-ANNUAL ($200 Jan-Jun / $200 Jul-Dec) | C38: $400/yr | D38: Third-party - confirm
A39: Airline Fee Credit (Aspire) | B39: QUARTERLY ($50 per quarter) | C39: $200/yr | D39: PENDING - incidental fees vs airfare
A40: CLEAR+ Credit (Aspire) | B40: CALENDAR-YEAR | C40: $219/yr | D40: Third-party - confirm
A41: Chase Travel hotel credit (CSP) | B41: CARDMEMBER-YEAR | C41: $100/yr | D41: OFFICIAL - Chase.com
A42: DoorDash non-restaurant credit (CSP) | B42: MONTHLY | C42: $10/mo through 12/31/2027 | D42: Third-party - confirm
A43: Instacart credit (CSP) | B43: MONTHLY | C43: unknown | D43: PENDING
A44: Global Entry/TSA/NEXUS (CSP) | B44: MULTI-YEAR (4 yr) | C44: up to $120 | D44: Third-party - confirm
A45: CLEAR+ Credit (Amex Green) | B45: CALENDAR-YEAR | C45: $219 | D45: Third-party - confirm
A46: Turo credit (Citi AA Plat) | B46: ONE-TIME, expires 2026-10-18 | C46: up to $30/trip, max $180 | D46: Issuer/Turo page
A47: Disney Streaming Credit (BCE) | B47: MONTHLY | C47: $7/mo up to $84/yr | D47: OFFICIAL - Amex.com
A48: Home Chef credit (BCE) | B48: MONTHLY | C48: up to $15/mo | D48: PENDING
... A50: Robinhood Gold membership | B50: YEARLY (monthly billing) | C50: $5/mo = $60/yr | D50: Counted in the annual fee
